Workbook

Sheet MAP
C1: top of tower
B2: 59f | C2: 59f
B3: ki | C3: 青 | D3: あか
A4: あお | B4: 黄 | C4: mido
B5: mura | C5: 緑 | D5: きいろ
A6: き | B6: aka | C6: 紫 | D6: みど
B7: ao | C7: むら | D7: 赤
B8: 黒 | C8: 黒 | G8: ｲﾛ ｲｯｶｲﾂﾞﾂ
B9: 黒 | C9: 黒 | D9: 黒
B10: 黒 | C10: 黒 | D10: 黒
A11: 黒 | B11: 黒 | C11: 黒 | D11: 黒
B12: 黒 | C12: 黒 | D12: 黒
B13: 黒 | C13: 黒 | D13: 黒
A14: 黒 | B14: 黒 | C14: 黒
B15: 黒 | C15: 黒 | D15: 黒
B16: 異 | C16: 異 | D16: 黒
B17: 異 | C17: 異 | D17: 異
A18: 黒 | B18: 異 | C18: 異
B19: 異 | C19: 異 | D19: 異
B20: 異 | C20: 異 | D20: 黒
B21: 異 | C21: 異 | D21: 異
A22: 黒 | B22: 異 | C22: 異
B23: 異 | C23: 異 | D23: 異
B24: 金 | C24: 金
A25: 金 | B25: 金 | C25: 金
A26: 金 | B26: 金 | D26: 顔
A27: 炎 | B27: 炎 | D27: 顔 | E27: 顔
A28: 炎 | B28: 炎 | D28: 顔
A29: 炎 | B29: 炎 | D29: 顔 | E29: 顔
A30: 炎 | B30: 炎 | D30: 顔
A31: 炎 | B31: 炎 | D31: 顔 | E31: 顔
A32: 炎 | B32: 炎 | D32: 顔
A33: 炎 | B33: 炎 | D33: 顔 | E33: 顔 | G33: ファイアーエリア
B34: 顔 | C34: 顔 | D34: 顔
B35: 顔 | C35: 顔 | D35: 顔 | G35: フェイスエリア
B36: 氷 | C36: 氷
B37: 氷 | C37: 氷 | D37: 氷
B38: 氷 | C38: 氷
B39: 氷 | C39: 氷 | D39: 氷
B40: 氷 | C40: 氷
...

Sheet MAP_ELV
C1: top of tower | F1: 60f | H1: タワーではヘクスごとに2ウェーブの戦闘を行う。
B2: 59f | C2: 59f | F2: 59f | H2: 出現するタイプが2種類、合計出現数が決まっていて、どちらがどれだけ出てくるかはランダム
B3: ki | C3: 青 | D3: あか | F3: 58f
A4: あお | B4: 黄 | C4: mido | F4: 57f | H4: 10
B5: mura | C5: 緑 | D5: きいろ | F5: 56f | H5: tanaka
A6: き | B6: aka | C6: 紫 | D6: みど | F6: 55f | H6: いぬ | I6: 1.5 | J6: ちわ
B7: ao | C7: むら | D7: 赤 | F7: 54f | H7: 42
B8: 黒 | C8: 黒 | F8: 53f | H8: 海
B9: 黒 | C9: 黒 | D9: 黒 | F9: 52f | H9: 090-9863-4829
B10: 黒 | C10: 黒 | D10: 黒 | F10: 51f
A11: 黒 | B11: 黒 | C11: 黒 | D11: 黒 | F11: 50f
B12: 黒 | C12: 黒 | D12: 黒 | F12: 49f
B13: 黒 | C13: 黒 | D13: 黒 | F13: 48f
A14: 黒 | B14: 黒 | C14: 黒 | F14: 47f
B15: 黒 | C15: 黒 | D15: 黒 | F15: 46f
B16: 異 | C16: 異 | D16: 黒 | F16: 45f
B17: 異 | C17: 異 | D17: 異 | F17: 44f
A18: 黒 | B18: 異 | C18: 異 | F18: 43f
B19: 異 | C19: 異 | D19: 異 | F19: 42f
B20: 異 | C20: 異 | D20: 黒 | F20: 41f
B21: 異 | C21: 異 | D21: 異 | F21: 40f
A22: 黒 | B22: 異 | C22: 異 | F22: 39f
B23: 異 | C23: 異 | D23: 異 | F23: 38f
B24: 金 | C24: 金 | F24: 37f
A25: 金 | B25: 金 | C25: 金 | F25: 36f
A26: 金 | B26: 金 | D26: 顔 | F26: 35f
A27: 炎 | B27: 炎 | D27: 顔 | E27: 顔 | F27: 34f
A28: 炎 | B28: 炎 | D28: 顔 | F28: 33f
A29: 炎 | B29: 炎 | D29: 顔 | E29: 顔 | F29: 32f
A30: 炎 | B30: 炎 | D30: 顔 | F30: 31f
A31: 炎 | B31: 炎 | D31: 顔 | E31: 顔 | F31: 30f
A32: 炎 | B32: 炎 | D32: 顔 | F32: 29f
A33: 炎 | B33: 炎 | D33: 顔 | E33: 顔 | F33: 28f
B34: 顔 | C34: 顔 | D34: 顔 | F34: 27f
B35: 顔 | C35: 顔 | D35: 顔 | F35: 26f | G35: フェイスエリア
B36: 氷 | C36: 氷 | F36: 25f
B37: 氷 | C37: 氷 | D37: 氷 | F37: 24f
B38: 氷 | C38: 氷 | F38: 23f
B39: 氷 | C39: 氷 | D39: 氷 | F39: 22f
B40: 氷 | C40: 氷 | F40: 21f
...

Sheet Sheet1
B1: 種類 | C1: 出現敵 | D1: 生命力 | E1: 移動速度 | F1: 移動距離(m) | G1: 移動間隔(秒) | H1: 攻撃射程(m) | I1: 攻撃頻度 | J1: 攻撃力 | K1: 重量 | L1: デバフ抵抗 | M1: 大きさ | N1: テクスチャ | O1: フレーム | R1: 種類 | S1: 出現敵 | T1: 生命力 | U1: 移動速度 | V1: 移動距離(m) | W1: 移動間隔(秒) | X1: 攻撃射程(m) | Y1: 攻撃頻度 | Z1: 攻撃力 | AA1: 重量 | AB1: デバフ抵抗 | AC1: 大きさ | AD1: テクスチャ | AE1: フレーム
A2: 0 | B2: スウォーム2 | C2: 9 | D2: =T2*20 -> 1000 | E2: 3 | F2: 6 | G2: 0.5 | H2: 4 | I2: 0.5 | J2: 1 | K2: 5 | L2: 0 | M2: 0.5 | N2: en003 | O2: 0 | Q2: 0 | R2: スウォーム | S2: 9 | T2: 50 | U2: 3 | V2: 6 | W2: 0.5 | X2: 4 | Y2: 0.5 | Z2: 1 | AA2: 5 | AB2: 0 | AC2: 0.5 | AD2: en003 | AE2: 0
A3: 1 | B3: フライ2 | C3: 4 | D3: =T3*20 -> 2000 | E3: 2.5 | F3: 4.5 | G3: 0.45 | H3: 6 | I3: 0.5 | J3: 1 | K3: 10 | L3: 0 | M3: 0.75 | N3: en003 | O3: 1 | Q3: 1 | R3: フライ | S3: 4 | T3: 100 | U3: 2.5 | V3: 4.5 | W3: 0.45 | X3: 6 | Y3: 0.5 | Z3: 1 | AA3: 10 | AB3: 0 | AC3: 0.75 | AD3: en003 | AE3: 1
A4: 2 | B4: スピリット2 | C4: 8 | D4: =T4*20 -> 3000 | E4: 1.6 | F4: 6 | G4: 0.4 | H4: 6 | I4: 0.5 | J4: 1 | K4: 45 | L4: 50 | M4: 1 | N4: en003 | O4: 2 | Q4: 2 | R4: スピリット | S4: 8 | T4: 150 | U4: 1.6 | V4: 6 | W4: 0.4 | X4: 6 | Y4: 0.5 | Z4: 1 | AA4: 45 | AB4: 50 | AC4: 1 | AD4: en003 | AE4: 2
A5: 3 | B5: マノウォー2 | C5: 3 | D5: =T5*20 -> 4000 | E5: 1 | F5: 0.5 | G5: 0.1 | H5: 8 | I5: 1 | J5: 1 | K5: 15 | L5: 50 | M5: 1 | N5: en003 | O5: 3 | Q5: 3 | R5: マノウォー | S5: 3 | T5: 200 | U5: 1 | V5: 0.5 | W5: 0.1 | X5: 8 | Y5: 1 | Z5: 1 | AA5: 15 | AB5: 50 | AC5: 1 | AD5: en003 | AE5: 3
A6: 4 | B6: ゴブリン2 | C6: 8 | D6: =T6*20 -> 4000 | E6: 10 | F6: 0.8 | G6: 0.25 | H6: 4 | I6: 0.5 | J6: 1 | K6: 35 | L6: 0 | M6: 0.5 | N6: en001 | O6: 2 | Q6: 4 | R6: ゴブリン | S6: 8 | T6: 200 | U6: 10 | V6: 0.8 | W6: 0.25 | X6: 4 | Y6: 0.5 | Z6: 1 | AA6: 35 | AB6: 0 | AC6: 0.5 | AD6: en001 | AE6: 2
A7: 5 | B7: コボルド2 | C7: 6 | D7: =T7*20 -> 5000 | E7: 8 | F7: 1 | G7: 0.35 | H7: 6 | I7: 0.5 | J7: 1 | K7: 55 | L7: 50 | M7: 0.75 | N7: en002 | O7: 3 | Q7: 5 | R7: コボルド | S7: 6 | T7: 250 | U7: 8 | V7: 1 | W7: 0.35 | X7: 6 | Y7: 0.5 | Z7: 1 | AA7: 55 | AB7: 50 | AC7: 0.75 | AD7: en002 | AE7: 3
A8: 6 | B8: オーク2 | C8: 6 | D8: =T8*20 -> 6000 | E8: 7 | F8: 0.9 | G8: 0.5 | H8: 8 | I8: 0.5 | J8: 1 | K8: 75 | L8: 0 | M8: 0.75 | N8: en001 | O8: 0 | Q8: 6 | R8: オーク | S8: 6 | T8: 300 | U8: 7 | V8: 0.9 | W8: 0.5 | X8: 8 | Y8: 0.5 | Z8: 1 | AA8: 75 | AB8: 0 | AC8: 0.75 | AD8: en001 | AE8: 0
A9: 7 | B9: オーガ2 | C9: 3 | D9: =T9*20 -> 8000 | E9: 6 | F9: 1.25 | G9: 0.35 | H9: 8 | I9: 0.5 | J9: 1 | K9: 110 | L9: 50 | M9: 1 | N9: en002 | O9: 2 | Q9: 7 | R9: オーガ | S9: 3 | T9: 400 | U9: 6 | V9: 1.25 | W9: 0.35 | X9: 8 | Y9: 0.5 | Z9: 1 | AA9: 110 | AB9: 50 | AC9: 1 | AD9: en002 | AE9: 2
A10: 8 | B10: ゴーレム2 | C10: 1 | D10: =T10*20 -> 20000 | E10: 2 | F10: 3.6 | G10: 0.6 | H10: 4 | I10: 1 | J10: 1 | K10: 110 | L10: 50 | M10: 1.25 | N10: en002 | O10: 1 | Q10: 8 | R10: ゴーレム | S10: 1 | T10: 1000 | U10: 2 | V10: 3.6 | W10: 0.6 | X10: 4 | Y10: 1 | Z10: 1 | AA10: 110 | AB10: 50 | AC10: 1.25 | AD10: en002 | AE10: 1
A12: ルームコード(x座標(0~4)+(floor*5))の値によって登場する2種類の雑魚が決まる
L13: 1 | M13: 2
B14: 0 | C14: 1 | D14: 2 | E14: 3 | F14: 4 | H14: 1編成目はRCを9で割った余り | K14: 1 | L14: =MOD(K14,9) -> 1 | M14: =MOD(K14+3,8) -> 4
A15: 0 | B15: =B$14+$A15*5 -> 0 | C15: =C$14+$A15*5 -> 1 | D15: =D$14+$A15*5 -> 2 | E15: =E$14+$A15*5 -> 3 | F15: =F$14+$A15*5 -> 4 | H15: 2編成目はRCを8で割った余り | K15: 2 | L15: =MOD(K15,9) -> 2 | M15: =MOD(K15+3,8) -> 5
A16: 1 | B16: =B$14+$A16*5 -> 5 | C16: =C$14+$A16*5 -> 6 | D16: =D$14+$A16*5 -> 7 | E16: =E$14+$A16*5 -> 8 | F16: =F$14+$A16*5 -> 9 | K16: 3 | L16: =MOD(K16,9) -> 3 | M16: =MOD(K16+3,8) -> 6
A17: 2 | B17: =B$14+$A17*5 -> 10 | C17: =C$14+$A17*5 -> 11 | D17: =D$14+$A17*5 -> 12 | E17: =E$14+$A17*5 -> 13 | F17: =F$14+$A17*5 -> 14 | K17: 4 | L17: =MOD(K17,9) -> 4 | M17: =MOD(K17+3,8) -> 7
A18: 3 | B18: =B$14+$A18*5 -> 15 | C18: =C$14+$A18*5 -> 16 | D18: =D$14+$A18*5 -> 17 | E18: =E$14+$A18*5 -> 18 | F18: =F$14+$A18*5 -> 19 | K18: 5 | L18: =MOD(K18,9) -> 5 | M18: =MOD(K18+3,8) -> 0
A19: 4 | B19: =B$14+$A19*5 -> 20 | C19: =C$14+$A19*5 -> 21 | D19: =D$14+$A19*5 -> 22 | E19: =E$14+$A19*5 -> 23 | F19: =F$14+$A19*5 -> 24 | K19: 6 | L19: =MOD(K19,9) -> 6 | M19: =MOD(K19+3,8) -> 1
A20: 5 | B20: =B$14+$A20*5 -> 25 | C20: =C$14+$A20*5 -> 26 | D20: =D$14+$A20*5 -> 27 | E20: =E$14+$A20*5 -> 28 | F20: =F$14+$A20*5 -> 29 | K20: 7 | L20: =MOD(K20,9) -> 7 | M20: =MOD(K20+3,8) -> 2
A21: 6 | B21: =B$14+$A21*5 -> 30 | C21: =C$14+$A21*5 -> 31 | D21: =D$14+$A21*5 -> 32 | E21: =E$14+$A21*5 -> 33 | F21: =F$14+$A21*5 -> 34 | K21: 8 | L21: =MOD(K21,9) -> 8 | M21: =MOD(K21+3,8) -> 3
A22: 7 | B22: =B$14+$A22*5 -> 35 | C22: =C$14+$A22*5 -> 36 | D22: =D$14+$A22*5 -> 37 | E22: =E$14+$A22*5 -> 38 | F22: =F$14+$A22*5 -> 39 | K22: 9 | L22: =MOD(K22,9) -> 0 | M22: =MOD(K22+3,8) -> 4
A23: 8 | B23: =B$14+$A23*5 -> 40 | C23: =C$14+$A23*5 -> 41 | D23: =D$14+$A23*5 -> 42 | E23: =E$14+$A23*5 -> 43 | F23: =F$14+$A23*5 -> 44 | K23: 10 | L23: =MOD(K23,9) -> 1 | M23: =MOD(K23+3,8) -> 5
A24: 9 | B24: =B$14+$A24*5 -> 45 | C24: =C$14+$A24*5 -> 46 | D24: =D$14+$A24*5 -> 47 | E24: =E$14+$A24*5 -> 48 | F24: =F$14+$A24*5 -> 49 | K24: 11 | L24: =MOD(K24,9) -> 2 | M24: =MOD(K24+3,8) -> 6
A25: 10 | B25: =B$14+$A25*5 -> 50 | C25: =C$14+$A25*5 -> 51 | D25: =D$14+$A25*5 -> 52 | E25: =E$14+$A25*5 -> 53 | F25: =F$14+$A25*5 -> 54 | K25: 12 | L25: =MOD(K25,9) -> 3 | M25: =MOD(K25+3,8) -> 7
K26: 13 | L26: =MOD(K26,9) -> 4 | M26: =MOD(K26+3,8) -> 0
K27: 14 | L27: =MOD(K27,9) -> 5 | M27: =MOD(K27+3,8) -> 1
K28: 15 | L28: =MOD(K28,9) -> 6 | M28: =MOD(K28+3,8) -> 2
K29: 16 | L29: =MOD(K29,9) -> 7 | M29: =MOD(K29+3,8) -> 3
K30: 17 | L30: =MOD(K30,9) -> 8 | M30: =MOD(K30+3,8) -> 4
K31: 18 | L31: =MOD(K31,9) -> 0 | M31: =MOD(K31+3,8) -> 5
K32: 19 | L32: =MOD(K32,9) -> 1 | M32: =MOD(K32+3,8) -> 6
K33: 20 | L33: =MOD(K33,9) -> 2 | M33: =MOD(K33+3,8) -> 7
K34: 21 | L34: =MOD(K34,9) -> 3 | M34: =MOD(K34+3,8) -> 0
K35: 22 | L35: =MOD(K35,9) -> 4 | M35: =MOD(K35+3,8) -> 1
K36: 23 | L36: =MOD(K36,9) -> 5 | M36: =MOD(K36+3,8) -> 2
K37: 24 | L37: =MOD(K37,9) -> 6 | M37: =MOD(K37+3,8) -> 3
... K73: 60 | L73: =MOD(K73,9) -> 6 | M73: =MOD(K73+3,8) -> 7

Sheet visual
A1: =MAP!A1 -> 0 | C1: =MAP!B1 -> 0 | E1: =MAP!C1 -> top of tower | G1: =MAP!D1 -> 0 | I1: =MAP!E1 -> 0 | O1: ##このページは人間が確認するための疑似ヘクスマップ
B2: =MAP!A2 -> 0 | D2: =MAP!B2 -> 59f | F2: =MAP!C2 -> 59f | H2: =MAP!D2 -> 0
A3: =MAP!A3 -> 0 | C3: =MAP!B3 -> ki | E3: =MAP!C3 -> 青 | G3: =MAP!D3 -> あか | I3: =MAP!E3 -> 0 | O3: アドベンチャーパートのヘクスマップ上を歩くデモを作るか。 マップデータは "C:\Users\user\.antigravity\game\files\MAP\MAP001.xlsx" のひとつめのタブにある。 これの偶数行めを半マスずらして配置するヘクス上のマップになる。模式図でこんな感じになる。(添付画像) マップの中心にキャラクタ(紫苑)もミニキャラがいて、画面横向きには５へクス程度の範囲が表示される。 ヘクスをタップするとキャラクターがジャンプして移動する。
B4: =MAP!A4 -> あお | D4: =MAP!B4 -> 黄 | F4: =MAP!C4 -> mido | H4: =MAP!D4 -> 0 | O4: マップには一旦水域を水色、密林は緑色で塗っておいてもらおうか、落ち着いたら画像ファイルを表示するようにするので対応できるようにしておいて。 マップの各ヘクスには、１踏破したかどうか ２潜んでいる敵のレベル ３潜んでいる魔女のレベル というデータがあります。平行して作っておいてください。いまのところは全て０ (未踏破、敵いない、魔女いない）で埋めておいて。 タイトルから一歩入ったあとに表示されるメニューにマップデモ として入口を作って。
A5: =MAP!A5 -> 0 | C5: =MAP!B5 -> mura | E5: =MAP!C5 -> 緑 | G5: =MAP!D5 -> きいろ | I5: =MAP!E5 -> 0 | O5: fieldフォルダにm(a,1)r.jpg のような画像がある。a,1はエクセル上の座標(0始まりではない) a,1のヘクスの背景にその画像を使う。
B6: =MAP!A6 -> き | D6: =MAP!B6 -> aka | F6: =MAP!C6 -> 紫 | H6: =MAP!D6 -> みど | O6: x1 などは汎用背景。m(x1).jpgを使用してください。密林はwoods 海はゲーム内時間が午前、午後の時はsea _day、夜の間はsea_nightを使用してください。未踏破m(unexplored).jpg
A7: =MAP!A7 -> 0 | C7: =MAP!B7 -> ao | E7: =MAP!C7 -> むら | G7: =MAP!D7 -> 赤 | I7: =MAP!E7 -> 0 | O7: 横9ヘクスまで見える広域マップボタンも搭載
B8: =MAP!A8 -> 0 | D8: =MAP!B8 -> 黒 | F8: =MAP!C8 -> 黒 | H8: =MAP!D8 -> 0 | O8: 移動のルール
A9: =MAP!A9 -> 0 | C9: =MAP!B9 -> 黒 | E9: =MAP!C9 -> 黒 | G9: =MAP!D9 -> 黒 | I9: =MAP!E9 -> 0 | O9: 踏破済のエリアか、隣接したことのある水域、密林エリアの画像が表示される。
B10: =MAP!A10 -> 0 | D10: =MAP!B10 -> 黒 | F10: =MAP!C10 -> 黒 | H10: =MAP!D10 -> 黒 | O10: 隣接した未踏破のエリアはm(adjacent).jpgが表示される
A11: =MAP!A11 -> 黒 | C11: =MAP!B11 -> 黒 | E11: =MAP!C11 -> 黒 | G11: =MAP!D11 -> 黒 | I11: =MAP!E11 -> 0 | O11: 隣接していない未踏破のヘクスはm(unexplored).jpgが表示される。
B12: =MAP!A12 -> 0 | D12: =MAP!B12 -> 黒 | F12: =MAP!C12 -> 黒 | H12: =MAP!D12 -> 黒 | O12: そのヘクスにいる敵の属性によってmap_eff1.jpg~map_eff5.jpg の敵に気配が見える。
A13: =MAP!A13 -> 0 | C13: =MAP!B13 -> 黒 | E13: =MAP!C13 -> 黒 | G13: =MAP!D13 -> 黒 | I13: =MAP!E13 -> 0 | O13: map_effは背景画像の上に不透明度0～50%でゆらめいている。
B14: =MAP!A14 -> 黒 | D14: =MAP!B14 -> 黒 | F14: =MAP!C14 -> 黒 | H14: =MAP!D14 -> 0
A15: =MAP!A15 -> 0 | C15: =MAP!B15 -> 黒 | E15: =MAP!C15 -> 黒 | G15: =MAP!D15 -> 黒 | I15: =MAP!E15 -> 0
B16: =MAP!A16 -> 0 | D16: =MAP!B16 -> 異 | F16: =MAP!C16 -> 異 | H16: =MAP!D16 -> 黒
A17: =MAP!A17 -> 0 | C17: =MAP!B17 -> 異 | E17: =MAP!C17 -> 異 | G17: =MAP!D17 -> 異 | I17: =MAP!E17 -> 0
B18: =MAP!A18 -> 黒 | D18: =MAP!B18 -> 異 | F18: =MAP!C18 -> 異 | H18: =MAP!D18 -> 0
A19: =MAP!A19 -> 0 | C19: =MAP!B19 -> 異 | E19: =MAP!C19 -> 異 | G19: =MAP!D19 -> 異 | I19: =MAP!E19 -> 0
B20: =MAP!A20 -> 0 | D20: =MAP!B20 -> 異 | F20: =MAP!C20 -> 異 | H20: =MAP!D20 -> 黒
A21: =MAP!A21 -> 0 | C21: =MAP!B21 -> 異 | E21: =MAP!C21 -> 異 | G21: =MAP!D21 -> 異 | I21: =MAP!E21 -> 0
B22: =MAP!A22 -> 黒 | D22: =MAP!B22 -> 異 | F22: =MAP!C22 -> 異 | H22: =MAP!D22 -> 0
A23: =MAP!A23 -> 0 | C23: =MAP!B23 -> 異 | E23: =MAP!C23 -> 異 | G23: =MAP!D23 -> 異 | I23: =MAP!E23 -> 0
B24: =MAP!A24 -> 0 | D24: =MAP!B24 -> 金 | F24: =MAP!C24 -> 金 | H24: =MAP!D24 -> 0
A25: =MAP!A25 -> 金 | C25: =MAP!B25 -> 金 | E25: =MAP!C25 -> 金 | G25: =MAP!D25 -> 0 | I25: =MAP!E25 -> 0
B26: =MAP!A26 -> 金 | D26: =MAP!B26 -> 金 | F26: =MAP!C26 -> 0 | H26: =MAP!D26 -> 顔
A27: =MAP!A27 -> 炎 | C27: =MAP!B27 -> 炎 | E27: =MAP!C27 -> 0 | G27: =MAP!D27 -> 顔 | I27: =MAP!E27 -> 顔
B28: =MAP!A28 -> 炎 | D28: =MAP!B28 -> 炎 | F28: =MAP!C28 -> 0 | H28: =MAP!D28 -> 顔
A29: =MAP!A29 -> 炎 | C29: =MAP!B29 -> 炎 | E29: =MAP!C29 -> 0 | G29: =MAP!D29 -> 顔 | I29: =MAP!E29 -> 顔
B30: =MAP!A30 -> 炎 | D30: =MAP!B30 -> 炎 | F30: =MAP!C30 -> 0 | H30: =MAP!D30 -> 顔
A31: =MAP!A31 -> 炎 | C31: =MAP!B31 -> 炎 | E31: =MAP!C31 -> 0 | G31: =MAP!D31 -> 顔 | I31: =MAP!E31 -> 顔
B32: =MAP!A32 -> 炎 | D32: =MAP!B32 -> 炎 | F32: =MAP!C32 -> 0 | H32: =MAP!D32 -> 顔
A33: =MAP!A33 -> 炎 | C33: =MAP!B33 -> 炎 | E33: =MAP!C33 -> 0 | G33: =MAP!D33 -> 顔 | I33: =MAP!E33 -> 顔
B34: =MAP!A34 -> 0 | D34: =MAP!B34 -> 顔 | F34: =MAP!C34 -> 顔 | H34: =MAP!D34 -> 顔
A35: =MAP!A35 -> 0 | C35: =MAP!B35 -> 顔 | E35: =MAP!C35 -> 顔 | G35: =MAP!D35 -> 顔 | I35: =MAP!E35 -> 0
B36: =MAP!A36 -> 0 | D36: =MAP!B36 -> 氷 | F36: =MAP!C36 -> 氷 | H36: =MAP!D36 -> 0
A37: =MAP!A37 -> 0 | C37: =MAP!B37 -> 氷 | E37: =MAP!C37 -> 氷 | G37: =MAP!D37 -> 氷 | I37: =MAP!E37 -> 0
B38: =MAP!A38 -> 0 | D38: =MAP!B38 -> 氷 | F38: =MAP!C38 -> 氷 | H38: =MAP!D38 -> 0
A39: =MAP!A39 -> 0 | C39: =MAP!B39 -> 氷 | E39: =MAP!C39 -> 氷 | G39: =MAP!D39 -> 氷 | I39: =MAP!E39 -> 0
B40: =MAP!A40 -> 0 | D40: =MAP!B40 -> 氷 | F40: =MAP!C40 -> 氷 | H40: =MAP!D40 -> 0
...
